Workbook

Sheet Channels
A1: Enabled | B1: Channel | C1: Name | D1: Color | E1: Source* | F1: Socket* | G1: Gain* | H1: Pad* | I1: Phantom* | J1: Mute | K1: Fader Level | L1: HPF On | M1: HPF Value | N1: Main Mix | P1: =CONCATENATE("Grp1 - ",Groups!P2) -> Grp1 - Grp1 | Q1: =CONCATENATE("Grp2 - ",Groups!P3) -> Grp2 - Grp2 | R1: =CONCATENATE("Grp3 - ",Groups!P4) -> Grp3 - Grp3 | S1: =CONCATENATE("Grp4 - ",Groups!P5) -> Grp4 - Grp4 | T1: =CONCATENATE("Grp5 - ",Groups!P6) -> Grp5 - Grp5 | U1: =CONCATENATE("Grp6 - ",Groups!P7) -> Grp6 - Grp6 | V1: =CONCATENATE("Grp7 - ",Groups!P8) -> Grp7 - Grp7 | W1: =CONCATENATE("Grp8 - ",Groups!$P9) -> Grp8 - Grp8 | Y1: =CONCATENATE("StGrp1 - ",Groups!U2) -> StGrp1 - StGrp1 | Z1: =CONCATENATE("StGrp2 - ",Groups!U3) -> StGrp2 - StGrp2 | AA1: =CONCATENATE("StGrp3 - ",Groups!U4) -> StGrp3 - StGrp3 | AB1: =CONCATENATE("StGrp4 - ",Groups!U5) -> StGrp4 - StGrp4 | AC1: =CONCATENATE("StGrp5 - ",Groups!U6) -> StGrp5 - StGrp5 | AD1: =CONCATENATE("StGrp6 - ",Groups!U7) -> StGrp6 - StGrp6 | AE1: =CONCATENATE("StGrp7 - ",Groups!U8) -> StGrp7 - StGrp7 | AF1: =CONCATENATE("StGrp8 - ",Groups!U9) -> StGrp8 - StGrp8 | AH1: Recording | AI1: Record Arm | AK1: =CONCATENATE("DCA1 - ",Groups!B2) -> DCA1 - Dca1 | AL1: =CONCATENATE("DCA2 - ",Groups!B3) -> DCA2 - Dca2 | AM1: =CONCATENATE("DCA3 - ",Groups!B4) -> DCA3 - Dca3 | AN1: =CONCATENATE("DCA4 - ",Groups!B5) -> DCA4 - Dca4 | AO1: =CONCATENATE("DCA5 - ",Groups!B6) -> DCA5 - Dca5 | AP1: =CONCATENATE("DCA6 - ",Groups!B7) -> DCA6 - Dca6 | AQ1: =CONCATENATE("DCA7 - ",Groups!B8) -> DCA7 - Dca7 | AR1: =CONCATENATE("DCA8 - ",Groups!B9) -> DCA8 - Dca8 | AS1: =CONCATENATE("DCA9 - ",Groups!B10) -> DCA9 - Dca9 | AT1: =CONCATENATE("DCA10 - ",Groups!B11) -> DCA10 - Dca10 | AU1: =CONCATENATE("DCA11 - ",Groups!B12) -> DCA11 - Dca11 | AV1: =CONCATENATE("DCA12 - ",Groups!B13) -> DCA12 - Dca12 | AW1: =CONCATENATE("DCA13 - ",Groups!B14) -> DCA13 - Dca13 | AX1: =CONCATENATE("DCA14 - ",Groups!B15) -> DCA14 - Dca14 | AY1: =CONCATENATE("DCA15 - ",Groups!B16) -> DCA15 - Dca15 | AZ1: =CONCATENATE("DCA16 - ",Groups!B17) -> DCA16 - Dca16 | BA1: =CONCATENATE("DCA17 - ",Groups!B18) -> DCA17 - | BB1: =CONCATENATE("DCA18 - ",Groups!B19) -> DCA18 - | BC1: =CONCATENATE("DCA19 - ",Groups!B20) -> DCA19 - | BD1: =CONCATENATE("DCA20 - ",Groups!B21) -> DCA20 - | BE1: =CONCATENATE("DCA21 - ",Groups!B22) -> DCA21 - | BF1: =CONCATENATE("DCA22 - ",Groups!B23) -> DCA22 - | BG1: =CONCATENATE("DCA23 - ",Groups!B24) -> DCA23 - | BH1: =CONCATENATE("DCA24 - ",Groups!B25) -> DCA24 - | BJ1: Mute1 | BK1: Mute2 | BL1: Mute3 | BM1: Mute4 | BN1: Mute5 | BO1: Mute6 | BP1: Mute7 | BQ1: Mute8 | BS1: DCA1 | BT1: DCA2 | BU1: DCA3 | BV1: DCA4 | BW1: DCA5 | BX1: DCA6 | BY1: DCA7 | BZ1: DCA8 | CA1: DCA9 | CB1: DCA10 | CC1: DCA11 | CD1: DCA12 | CE1: DCA13 | CF1: DCA14 | CG1: DCA15 | CH1: DCA16 | CI1: DCA17 | CJ1: DCA18 | CK1: DCA19 | CL1: DCA20 | CM1: DCA21 | CN1: DCA22 | CO1: DCA23 | CP1: DCA24 | CR1: Grp1 | CS1: Grp2 | CT1: Grp3 | CU1: Grp4 | CV1: Grp5 | CW1: Grp6 | CX1: Grp7 | CY1: Grp8 | CZ1: Grp9 | DA1: Grp10 | DB1: Grp11 | DC1: Grp12 | DE1: StGrp1 | DF1: StGrp2 | DG1: StGrp3 | DH1: StGrp4 | DI1: StGrp5 | DJ1: StGrp6 | DK1: StGrp7 | DL1: StGrp8 | DM1: StGrp9 | DN1: StGrp10 | DO1: StGrp11 | DP1: StGrp12 | DQ1: Hidden Helper Cells – Please dont touch
A2: yes | B2: 1 | C2: TST001 | D2: blue | E2: SLink | F2: 1 | G2: 5 | H2: no | I2: no | J2: yes | K2: - | M2: 20 | N2: yes | P2: x | Y2: - | Z2: - | AA2: - | AB2: - | AC2: - | AD2: - | AE2: - | AF2: - | AH2: yes | AI2: yes | AK2: x | BJ2: - | BK2: - | BL2: - | BM2: - | BN2: - | BO2: - | BP2: - | BQ2: - | BS2: =IF(AK2="x","x",IF(AK2="-","-","")) -> x | BT2: =IF(AL2="x","x",IF(AL2="-","-","")) | BU2: =IF(AM2="x","x",IF(AM2="-","-","")) | BV2: =IF(AN2="x","x",IF(AN2="-","-","")) | BW2: =IF(AO2="x","x",IF(AO2="-","-","")) | BX2: =IF(AP2="x","x",IF(AP2="-","-","")) | BY2: =IF(AQ2="x","x",IF(AQ2="-","-","")) | BZ2: =IF(AR2="x","x",IF(AR2="-","-","")) | ... CP2: =IF(BH2="x","x",IF(BH2="-","-","")) | CR2: =IF(P2="x","x",IF(P2="-","-","")) -> x | CS2: =IF(Q2="x","x",IF(Q2="-","-","")) | CT2: =IF(R2="x","x",IF(R2="-","-","")) | CU2: =IF(S2="x","x",IF(S2="-","-","")) | CV2: =IF(T2="x","x",IF(T2="-","-","")) | CW2: =IF(U2="x","x",IF(U2="-","-","")) | CX2: =IF(V2="x","x",IF(V2="-","-","")) | CY2: =IF(W2="x","x",IF(W2="-","-","")) | CZ2: - | DA2: - | DB2: - | DC2: - | DE2: =IF(Y2="x","x",IF(Y2="-","-","")) -> - | DF2: =IF(Z2="x","x",IF(Z2="-","-","")) -> - | DG2: =IF(AA2="x","x",IF(AA2="-","-","")) -> - | DH2: =IF(AB2="x","x",IF(AB2="-","-","")) -> - | DI2: =IF(AC2="x","x",IF(AC2="-","-","")) -> - | DJ2: =IF(AD2="x","x",IF(AD2="-","-","")) -> - | DK2: =IF(AE2="x","x",IF(AE2="-","-","")) -> - | DL2: =IF(AF2="x","x",IF(AF2="-","-","")) -> - | DM2: - | DN2: - | DO2: - | DP2: -
A3: yes | B3: 2 | C3: TST002 | D3: blue | E3: SLink | F3: 2 | G3: 10 | H3: no | I3: yes | J3: no | L3: - | M3: 40 | N3: yes | Q3: x | Y3: - | Z3: - | AA3: - | AB3: - | AC3: - | AD3: - | AE3: - | AF3: - | AH3: yes | AI3: yes | AK3: x | BJ3: - | BK3: - | BL3: - | BM3: - | BN3: - | BO3: - | BP3: - | BQ3: - | BS3: =IF(AK3="x","x",IF(AK3="-","-","")) -> x | BT3: =IF(AL3="x","x",IF(AL3="-","-","")) | BU3: =IF(AM3="x","x",IF(AM3="-","-","")) | BV3: =IF(AN3="x","x",IF(AN3="-","-","")) | BW3: =IF(AO3="x","x",IF(AO3="-","-","")) | BX3: =IF(AP3="x","x",IF(AP3="-","-","")) | BY3: =IF(AQ3="x","x",IF(AQ3="-","-","")) | BZ3: =IF(AR3="x","x",IF(AR3="-","-","")) | ... CP3: =IF(BH3="x","x",IF(BH3="-","-","")) | CR3: =IF(P3="x","x",IF(P3="-","-","")) | CS3: =IF(Q3="x","x",IF(Q3="-","-","")) -> x | CT3: =IF(R3="x","x",IF(R3="-","-","")) | CU3: =IF(S3="x","x",IF(S3="-","-","")) | CV3: =IF(T3="x","x",IF(T3="-","-","")) | CW3: =IF(U3="x","x",IF(U3="-","-","")) | CX3: =IF(V3="x","x",IF(V3="-","-","")) | CY3: =IF(W3="x","x",IF(W3="-","-","")) | CZ3: - | DA3: - | DB3: - | DC3: - | DE3: =IF(Y3="x","x",IF(Y3="-","-","")) -> - | DF3: =IF(Z3="x","x",IF(Z3="-","-","")) -> - | DG3: =IF(AA3="x","x",IF(AA3="-","-","")) -> - | DH3: =IF(AB3="x","x",IF(AB3="-","-","")) -> - | DI3: =IF(AC3="x","x",IF(AC3="-","-","")) -> - | DJ3: =IF(AD3="x","x",IF(AD3="-","-","")) -> - | DK3: =IF(AE3="x","x",IF(AE3="-","-","")) -> - | DL3: =IF(AF3="x","x",IF(AF3="-","-","")) -> - | DM3: - | DN3: - | DO3: - | DP3: -
A4: yes | B4: 3 | C4: TST003 | D4: blue | E4: SLink | F4: 3 | G4: 15 | H4: no | I4: no | J4: yes | K4: - | L4: yes | M4: 60 | N4: yes | R4: x | Y4: - | Z4: - | AA4: - | AB4: - | AC4: - | AD4: - | AE4: - | AF4: - | AH4: yes | AI4: yes | AK4: x | BJ4: - | BK4: - | BL4: - | BM4: - | BN4: - | BO4: - | BP4: - | BQ4: - | BS4: =IF(AK4="x","x",IF(AK4="-","-","")) -> x | BT4: =IF(AL4="x","x",IF(AL4="-","-","")) | BU4: =IF(AM4="x","x",IF(AM4="-","-","")) | BV4: =IF(AN4="x","x",IF(AN4="-","-","")) | BW4: =IF(AO4="x","x",IF(AO4="-","-","")) | BX4: =IF(AP4="x","x",IF(AP4="-","-","")) | BY4: =IF(AQ4="x","x",IF(AQ4="-","-","")) | BZ4: =IF(AR4="x","x",IF(AR4="-","-","")) | ... CP4: =IF(BH4="x","x",IF(BH4="-","-","")) | CR4: =IF(P4="x","x",IF(P4="-","-","")) | CS4: =IF(Q4="x","x",IF(Q4="-","-","")) | CT4: =IF(R4="x","x",IF(R4="-","-","")) -> x | CU4: =IF(S4="x","x",IF(S4="-","-","")) | CV4: =IF(T4="x","x",IF(T4="-","-","")) | CW4: =IF(U4="x","x",IF(U4="-","-","")) | CX4: =IF(V4="x","x",IF(V4="-","-","")) | CY4: =IF(W4="x","x",IF(W4="-","-","")) | CZ4: - | DA4: - | DB4: - | DC4: - | DE4: =IF(Y4="x","x",IF(Y4="-","-","")) -> - | DF4: =IF(Z4="x","x",IF(Z4="-","-","")) -> - | DG4: =IF(AA4="x","x",IF(AA4="-","-","")) -> - | DH4: =IF(AB4="x","x",IF(AB4="-","-","")) -> - | DI4: =IF(AC4="x","x",IF(AC4="-","-","")) -> - | DJ4: =IF(AD4="x","x",IF(AD4="-","-","")) -> - | DK4: =IF(AE4="x","x",IF(AE4="-","-","")) -> - | DL4: =IF(AF4="x","x",IF(AF4="-","-","")) -> - | DM4: - | DN4: - | DO4: - | DP4: -
A5: yes | B5: 4 | C5: TST004 | D5: blue | E5: SLink | F5: 4 | G5: 20 | H5: no | I5: yes | J5: no | L5: no | M5: 80 | N5: yes | S5: x | Y5: - | Z5: - | AA5: - | AB5: - | AC5: - | AD5: - | AE5: - | AF5: - | AH5: yes | AI5: yes | AK5: x | BJ5: - | BK5: - | BL5: - | BM5: - | BN5: - | BO5: - | BP5: - | BQ5: - | BS5: =IF(AK5="x","x",IF(AK5="-","-","")) -> x | BT5: =IF(AL5="x","x",IF(AL5="-","-","")) | BU5: =IF(AM5="x","x",IF(AM5="-","-","")) | BV5: =IF(AN5="x","x",IF(AN5="-","-","")) | BW5: =IF(AO5="x","x",IF(AO5="-","-","")) | BX5: =IF(AP5="x","x",IF(AP5="-","-","")) | BY5: =IF(AQ5="x","x",IF(AQ5="-","-","")) | BZ5: =IF(AR5="x","x",IF(AR5="-","-","")) | ... CP5: =IF(BH5="x","x",IF(BH5="-","-","")) | CR5: =IF(P5="x","x",IF(P5="-","-","")) | CS5: =IF(Q5="x","x",IF(Q5="-","-","")) | CT5: =IF(R5="x","x",IF(R5="-","-","")) | CU5: =IF(S5="x","x",IF(S5="-","-","")) -> x | CV5: =IF(T5="x","x",IF(T5="-","-","")) | CW5: =IF(U5="x","x",IF(U5="-","-","")) | CX5: =IF(V5="x","x",IF(V5="-","-","")) | CY5: =IF(W5="x","x",IF(W5="-","-","")) | CZ5: - | DA5: - | DB5: - | DC5: - | DE5: =IF(Y5="x","x",IF(Y5="-","-","")) -> - | DF5: =IF(Z5="x","x",IF(Z5="-","-","")) -> - | DG5: =IF(AA5="x","x",IF(AA5="-","-","")) -> - | DH5: =IF(AB5="x","x",IF(AB5="-","-","")) -> - | DI5: =IF(AC5="x","x",IF(AC5="-","-","")) -> - | DJ5: =IF(AD5="x","x",IF(AD5="-","-","")) -> - | DK5: =IF(AE5="x","x",IF(AE5="-","-","")) -> - | DL5: =IF(AF5="x","x",IF(AF5="-","-","")) -> - | DM5: - | DN5: - | DO5: - | DP5: -
A6: yes | B6: 5 | C6: TST005 | D6: blue | E6: SLink | F6: 5 | G6: 25 | H6: no | I6: no | J6: yes | K6: - | L6: yes | M6: 100 | N6: yes | T6: x | Y6: - | Z6: - | AA6: - | AB6: - | AC6: - | AD6: - | AE6: - | AF6: - | AH6: yes | AI6: yes | AK6: x | BJ6: - | BK6: - | BL6: - | BM6: - | BN6: - | BO6: - | BP6: - | BQ6: - | BS6: =IF(AK6="x","x",IF(AK6="-","-","")) -> x | BT6: =IF(AL6="x","x",IF(AL6="-","-","")) | BU6: =IF(AM6="x","x",IF(AM6="-","-","")) | BV6: =IF(AN6="x","x",IF(AN6="-","-","")) | BW6: =IF(AO6="x","x",IF(AO6="-","-","")) | BX6: =IF(AP6="x","x",IF(AP6="-","-","")) | BY6: =IF(AQ6="x","x",IF(AQ6="-","-","")) | BZ6: =IF(AR6="x","x",IF(AR6="-","-","")) | ... CP6: =IF(BH6="x","x",IF(BH6="-","-","")) | CR6: =IF(P6="x","x",IF(P6="-","-","")) | CS6: =IF(Q6="x","x",IF(Q6="-","-","")) | CT6: =IF(R6="x","x",IF(R6="-","-","")) | CU6: =IF(S6="x","x",IF(S6="-","-","")) | CV6: =IF(T6="x","x",IF(T6="-","-","")) -> x | CW6: =IF(U6="x","x",IF(U6="-","-","")) | CX6: =IF(V6="x","x",IF(V6="-","-","")) | CY6: =IF(W6="x","x",IF(W6="-","-","")) | CZ6: - | DA6: - | DB6: - | DC6: - | DE6: =IF(Y6="x","x",IF(Y6="-","-","")) -> - | DF6: =IF(Z6="x","x",IF(Z6="-","-","")) -> - | DG6: =IF(AA6="x","x",IF(AA6="-","-","")) -> - | DH6: =IF(AB6="x","x",IF(AB6="-","-","")) -> - | DI6: =IF(AC6="x","x",IF(AC6="-","-","")) -> - | DJ6: =IF(AD6="x","x",IF(AD6="-","-","")) -> - | DK6: =IF(AE6="x","x",IF(AE6="-","-","")) -> - | DL6: =IF(AF6="x","x",IF(AF6="-","-","")) -> - | DM6: - | DN6: - | DO6: - | DP6: -
A7: yes | B7: 6 | C7: TST006 | D7: blue | E7: SLink | F7: 6 | G7: 30 | H7: no | I7: yes | J7: no | L7: no | M7: 120 | N7: yes | U7: x | Y7: - | Z7: - | AA7: - | AB7: - | AC7: - | AD7: - | AE7: - | AF7: - | AH7: yes | AI7: yes | AK7: x | BJ7: - | BK7: - | BL7: - | BM7: - | BN7: - | BO7: - | BP7: - | BQ7: - | BS7: =IF(AK7="x","x",IF(AK7="-","-","")) -> x | BT7: =IF(AL7="x","x",IF(AL7="-","-","")) | BU7: =IF(AM7="x","x",IF(AM7="-","-","")) | BV7: =IF(AN7="x","x",IF(AN7="-","-","")) | BW7: =IF(AO7="x","x",IF(AO7="-","-","")) | BX7: =IF(AP7="x","x",IF(AP7="-","-","")) | BY7: =IF(AQ7="x","x",IF(AQ7="-","-","")) | BZ7: =IF(AR7="x","x",IF(AR7="-","-","")) | ... CP7: =IF(BH7="x","x",IF(BH7="-","-","")) | CR7: =IF(P7="x","x",IF(P7="-","-","")) | CS7: =IF(Q7="x","x",IF(Q7="-","-","")) | CT7: =IF(R7="x","x",IF(R7="-","-","")) | CU7: =IF(S7="x","x",IF(S7="-","-","")) | CV7: =IF(T7="x","x",IF(T7="-","-","")) | CW7: =IF(U7="x","x",IF(U7="-","-","")) -> x | CX7: =IF(V7="x","x",IF(V7="-","-","")) | CY7: =IF(W7="x","x",IF(W7="-","-","")) | CZ7: - | DA7: - | DB7: - | DC7: - | DE7: =IF(Y7="x","x",IF(Y7="-","-","")) -> - | DF7: =IF(Z7="x","x",IF(Z7="-","-","")) -> - | DG7: =IF(AA7="x","x",IF(AA7="-","-","")) -> - | DH7: =IF(AB7="x","x",IF(AB7="-","-","")) -> - | DI7: =IF(AC7="x","x",IF(AC7="-","-","")) -> - | DJ7: =IF(AD7="x","x",IF(AD7="-","-","")) -> - | DK7: =IF(AE7="x","x",IF(AE7="-","-","")) -> - | DL7: =IF(AF7="x","x",IF(AF7="-","-","")) -> - | DM7: - | DN7: - | DO7: - | DP7: -
A8: yes | B8: 7 | C8: TST007 | D8: blue | E8: SLink | F8: 7 | G8: 35 | H8: no | I8: no | J8: yes | K8: - | L8: yes | M8: 140 | N8: yes | V8: x | Y8: - | Z8: - | AA8: - | AB8: - | AC8: - | AD8: - | AE8: - | AF8: - | AH8: yes | AI8: yes | AK8: x | BJ8: - | BK8: - | BL8: - | BM8: - | BN8: - | BO8: - | BP8: - | BQ8: - | BS8: =IF(AK8="x","x",IF(AK8="-","-","")) -> x | BT8: =IF(AL8="x","x",IF(AL8="-","-","")) | BU8: =IF(AM8="x","x",IF(AM8="-","-","")) | BV8: =IF(AN8="x","x",IF(AN8="-","-","")) | BW8: =IF(AO8="x","x",IF(AO8="-","-","")) | BX8: =IF(AP8="x","x",IF(AP8="-","-","")) | BY8: =IF(AQ8="x","x",IF(AQ8="-","-","")) | BZ8: =IF(AR8="x","x",IF(AR8="-","-","")) | ... CP8: =IF(BH8="x","x",IF(BH8="-","-","")) | CR8: =IF(P8="x","x",IF(P8="-","-","")) | CS8: =IF(Q8="x","x",IF(Q8="-","-","")) | CT8: =IF(R8="x","x",IF(R8="-","-","")) | CU8: =IF(S8="x","x",IF(S8="-","-","")) | CV8: =IF(T8="x","x",IF(T8="-","-","")) | CW8: =IF(U8="x","x",IF(U8="-","-","")) | CX8: =IF(V8="x","x",IF(V8="-","-","")) -> x | CY8: =IF(W8="x","x",IF(W8="-","-","")) | CZ8: - | DA8: - | DB8: - | DC8: - | DE8: =IF(Y8="x","x",IF(Y8="-","-","")) -> - | DF8: =IF(Z8="x","x",IF(Z8="-","-","")) -> - | DG8: =IF(AA8="x","x",IF(AA8="-","-","")) -> - | DH8: =IF(AB8="x","x",IF(AB8="-","-","")) -> - | DI8: =IF(AC8="x","x",IF(AC8="-","-","")) -> - | DJ8: =IF(AD8="x","x",IF(AD8="-","-","")) -> - | DK8: =IF(AE8="x","x",IF(AE8="-","-","")) -> - | DL8: =IF(AF8="x","x",IF(AF8="-","-","")) -> - | DM8: - | DN8: - | DO8: - | DP8: -
A9: yes | B9: 8 | C9: TST008 | D9: blue | E9: SLink | F9: 8 | G9: 40 | H9: no | I9: yes | J9: no | L9: no | M9: 160 | N9: yes | W9: x | Y9: - | Z9: - | AA9: - | AB9: - | AC9: - | AD9: - | AE9: - | AF9: - | AH9: yes | AI9: yes | AK9: x | BJ9: - | BK9: - | BL9: - | BM9: - | BN9: - | BO9: - | BP9: - | BQ9: - | BS9: =IF(AK9="x","x",IF(AK9="-","-","")) -> x | BT9: =IF(AL9="x","x",IF(AL9="-","-","")) | BU9: =IF(AM9="x","x",IF(AM9="-","-","")) | BV9: =IF(AN9="x","x",IF(AN9="-","-","")) | BW9: =IF(AO9="x","x",IF(AO9="-","-","")) | BX9: =IF(AP9="x","x",IF(AP9="-","-","")) | BY9: =IF(AQ9="x","x",IF(AQ9="-","-","")) | BZ9: =IF(AR9="x","x",IF(AR9="-","-","")) | ... CP9: =IF(BH9="x","x",IF(BH9="-","-","")) | CR9: =IF(P9="x","x",IF(P9="-","-","")) | CS9: =IF(Q9="x","x",IF(Q9="-","-","")) | CT9: =IF(R9="x","x",IF(R9="-","-","")) | CU9: =IF(S9="x","x",IF(S9="-","-","")) | CV9: =IF(T9="x","x",IF(T9="-","-","")) | CW9: =IF(U9="x","x",IF(U9="-","-","")) | CX9: =IF(V9="x","x",IF(V9="-","-","")) | CY9: =IF(W9="x","x",IF(W9="-","-","")) -> x | CZ9: - | DA9: - | DB9: - | DC9: - | DE9: =IF(Y9="x","x",IF(Y9="-","-","")) -> - | DF9: =IF(Z9="x","x",IF(Z9="-","-","")) -> - | DG9: =IF(AA9="x","x",IF(AA9="-","-","")) -> - | DH9: =IF(AB9="x","x",IF(AB9="-","-","")) -> - | DI9: =IF(AC9="x","x",IF(AC9="-","-","")) -> - | DJ9: =IF(AD9="x","x",IF(AD9="-","-","")) -> - | DK9: =IF(AE9="x","x",IF(AE9="-","-","")) -> - | DL9: =IF(AF9="x","x",IF(AF9="-","-","")) -> - | DM9: - | DN9: - | DO9: - | DP9: -
A10: yes | B10: 9 | C10: TST009 | D10: blue | E10: SLink | F10: 9 | G10: 45 | H10: no | I10: no | J10: yes | K10: - | L10: yes | M10: 180 | N10: yes | P10: - | Q10: - | R10: - | S10: - | T10: - | U10: - | V10: - | W10: - | Y10: - | Z10: - | AA10: - | AB10: - | AC10: - | AD10: - | AE10: - | AF10: - | AH10: yes | AI10: yes | AK10: x | BJ10: - | BK10: - | BL10: - | BM10: - | BN10: - | BO10: - | BP10: - | BQ10: - | BS10: =IF(AK10="x","x",IF(AK10="-","-","")) -> x | BT10: =IF(AL10="x","x",IF(AL10="-","-","")) | BU10: =IF(AM10="x","x",IF(AM10="-","-","")) | BV10: =IF(AN10="x","x",IF(AN10="-","-","")) | BW10: =IF(AO10="x","x",IF(AO10="-","-","")) | BX10: =IF(AP10="x","x",IF(AP10="-","-","")) | BY10: =IF(AQ10="x","x",IF(AQ10="-","-","")) | BZ10: =IF(AR10="x","x",IF(AR10="-","-","")) | ... CP10: =IF(BH10="x","x",IF(BH10="-","-","")) | CR10: =IF(P10="x","x",IF(P10="-","-","")) -> - | CS10: =IF(Q10="x","x",IF(Q10="-","-","")) -> - | CT10: =IF(R10="x","x",IF(R10="-","-","")) -> - | CU10: =IF(S10="x","x",IF(S10="-","-","")) -> - | CV10: =IF(T10="x","x",IF(T10="-","-","")) -> - | CW10: =IF(U10="x","x",IF(U10="-","-","")) -> - | CX10: =IF(V10="x","x",IF(V10="-","-","")) -> - | CY10: =IF(W10="x","x",IF(W10="-","-","")) -> - | CZ10: - | DA10: - | DB10: - | DC10: - | DE10: =IF(Y10="x","x",IF(Y10="-","-","")) -> - | DF10: =IF(Z10="x","x",IF(Z10="-","-","")) -> - | DG10: =IF(AA10="x","x",IF(AA10="-","-","")) -> - | DH10: =IF(AB10="x","x",IF(AB10="-","-","")) -> - | DI10: =IF(AC10="x","x",IF(AC10="-","-","")) -> - | DJ10: =IF(AD10="x","x",IF(AD10="-","-","")) -> - | DK10: =IF(AE10="x","x",IF(AE10="-","-","")) -> - | DL10: =IF(AF10="x","x",IF(AF10="-","-","")) -> - | DM10: - | DN10: - | DO10: - | DP10: -
A11: yes | B11: 10 | C11: TST010 | D11: blue | E11: SLink | F11: 10 | G11: 50 | H11: no | I11: yes | J11: no | L11: no | M11: 200 | N11: yes | P11: - | Q11: - | R11: - | S11: - | T11: - | U11: - | V11: - | W11: - | Y11: - | Z11: - | AA11: - | AB11: - | AC11: - | AD11: - | AE11: - | AF11: - | AH11: yes | AI11: yes | AK11: x | BJ11: - | BK11: - | BL11: - | BM11: - | BN11: - | BO11: - | BP11: - | BQ11: - | BS11: =IF(AK11="x","x",IF(AK11="-","-","")) -> x | BT11: =IF(AL11="x","x",IF(AL11="-","-","")) | BU11: =IF(AM11="x","x",IF(AM11="-","-","")) | BV11: =IF(AN11="x","x",IF(AN11="-","-","")) | BW11: =IF(AO11="x","x",IF(AO11="-","-","")) | BX11: =IF(AP11="x","x",IF(AP11="-","-","")) | BY11: =IF(AQ11="x","x",IF(AQ11="-","-","")) | BZ11: =IF(AR11="x","x",IF(AR11="-","-","")) | ... CP11: =IF(BH11="x","x",IF(BH11="-","-","")) | CR11: =IF(P11="x","x",IF(P11="-","-","")) -> - | CS11: =IF(Q11="x","x",IF(Q11="-","-","")) -> - | CT11: =IF(R11="x","x",IF(R11="-","-","")) -> - | CU11: =IF(S11="x","x",IF(S11="-","-","")) -> - | CV11: =IF(T11="x","x",IF(T11="-","-","")) -> - | CW11: =IF(U11="x","x",IF(U11="-","-","")) -> - | CX11: =IF(V11="x","x",IF(V11="-","-","")) -> - | CY11: =IF(W11="x","x",IF(W11="-","-","")) -> - | CZ11: - | DA11: - | DB11: - | DC11: - | DE11: =IF(Y11="x","x",IF(Y11="-","-","")) -> - | DF11: =IF(Z11="x","x",IF(Z11="-","-","")) -> - | DG11: =IF(AA11="x","x",IF(AA11="-","-","")) -> - | DH11: =IF(AB11="x","x",IF(AB11="-","-","")) -> - | DI11: =IF(AC11="x","x",IF(AC11="-","-","")) -> - | DJ11: =IF(AD11="x","x",IF(AD11="-","-","")) -> - | DK11: =IF(AE11="x","x",IF(AE11="-","-","")) -> - | DL11: =IF(AF11="x","x",IF(AF11="-","-","")) -> - | DM11: - | DN11: - | DO11: - | DP11: -
A12: yes | B12: 11 | C12: TST011 | D12: blue | E12: SLink | F12: 11 | G12: 55 | H12: no | I12: no | J12: yes | K12: - | L12: yes | M12: 220 | N12: yes | P12: - | Q12: - | R12: - | S12: - | T12: - | U12: - | V12: - | W12: - | Y12: - | Z12: - | AA12: - | AB12: - | AC12: - | AD12: - | AE12: - | AF12: - | AH12: yes | AI12: yes | AK12: x | BJ12: - | BK12: - | BL12: - | BM12: - | BN12: - | BO12: - | BP12: - | BQ12: - | BS12: =IF(AK12="x","x",IF(AK12="-","-","")) -> x | BT12: =IF(AL12="x","x",IF(AL12="-","-","")) | BU12: =IF(AM12="x","x",IF(AM12="-","-","")) | BV12: =IF(AN12="x","x",IF(AN12="-","-","")) | BW12: =IF(AO12="x","x",IF(AO12="-","-","")) | BX12: =IF(AP12="x","x",IF(AP12="-","-","")) | BY12: =IF(AQ12="x","x",IF(AQ12="-","-","")) | BZ12: =IF(AR12="x","x",IF(AR12="-","-","")) | ... CP12: =IF(BH12="x","x",IF(BH12="-","-","")) | CR12: =IF(P12="x","x",IF(P12="-","-","")) -> - | CS12: =IF(Q12="x","x",IF(Q12="-","-","")) -> - | CT12: =IF(R12="x","x",IF(R12="-","-","")) -> - | CU12: =IF(S12="x","x",IF(S12="-","-","")) -> - | CV12: =IF(T12="x","x",IF(T12="-","-","")) -> - | CW12: =IF(U12="x","x",IF(U12="-","-","")) -> - | CX12: =IF(V12="x","x",IF(V12="-","-","")) -> - | CY12: =IF(W12="x","x",IF(W12="-","-","")) -> - | CZ12: - | DA12: - | DB12: - | DC12: - | DE12: =IF(Y12="x","x",IF(Y12="-","-","")) -> - | DF12: =IF(Z12="x","x",IF(Z12="-","-","")) -> - | DG12: =IF(AA12="x","x",IF(AA12="-","-","")) -> - | DH12: =IF(AB12="x","x",IF(AB12="-","-","")) -> - | DI12: =IF(AC12="x","x",IF(AC12="-","-","")) -> - | DJ12: =IF(AD12="x","x",IF(AD12="-","-","")) -> - | DK12: =IF(AE12="x","x",IF(AE12="-","-","")) -> - | DL12: =IF(AF12="x","x",IF(AF12="-","-","")) -> - | DM12: - | DN12: - | DO12: - | DP12: -
A13: yes | B13: 12 | C13: TST012 | D13: blue | E13: SLink | F13: 12 | G13: 60 | H13: no | I13: yes | J13: no | L13: no | M13: 240 | N13: yes | P13: - | Q13: - | R13: - | S13: - | T13: - | U13: - | V13: - | W13: - | Y13: - | Z13: - | AA13: - | AB13: - | AC13: - | AD13: - | AE13: - | AF13: - | AH13: yes | AI13: yes | AK13: x | BJ13: - | BK13: - | BL13: - | BM13: - | BN13: - | BO13: - | BP13: - | BQ13: - | BS13: =IF(AK13="x","x",IF(AK13="-","-","")) -> x | BT13: =IF(AL13="x","x",IF(AL13="-","-","")) | BU13: =IF(AM13="x","x",IF(AM13="-","-","")) | BV13: =IF(AN13="x","x",IF(AN13="-","-","")) | BW13: =IF(AO13="x","x",IF(AO13="-","-","")) | BX13: =IF(AP13="x","x",IF(AP13="-","-","")) | BY13: =IF(AQ13="x","x",IF(AQ13="-","-","")) | BZ13: =IF(AR13="x","x",IF(AR13="-","-","")) | ... CP13: =IF(BH13="x","x",IF(BH13="-","-","")) | CR13: =IF(P13="x","x",IF(P13="-","-","")) -> - | CS13: =IF(Q13="x","x",IF(Q13="-","-","")) -> - | CT13: =IF(R13="x","x",IF(R13="-","-","")) -> - | CU13: =IF(S13="x","x",IF(S13="-","-","")) -> - | CV13: =IF(T13="x","x",IF(T13="-","-","")) -> - | CW13: =IF(U13="x","x",IF(U13="-","-","")) -> - | CX13: =IF(V13="x","x",IF(V13="-","-","")) -> - | CY13: =IF(W13="x","x",IF(W13="-","-","")) -> - | CZ13: - | DA13: - | DB13: - | DC13: - | DE13: =IF(Y13="x","x",IF(Y13="-","-","")) -> - | DF13: =IF(Z13="x","x",IF(Z13="-","-","")) -> - | DG13: =IF(AA13="x","x",IF(AA13="-","-","")) -> - | DH13: =IF(AB13="x","x",IF(AB13="-","-","")) -> - | DI13: =IF(AC13="x","x",IF(AC13="-","-","")) -> - | DJ13: =IF(AD13="x","x",IF(AD13="-","-","")) -> - | DK13: =IF(AE13="x","x",IF(AE13="-","-","")) -> - | DL13: =IF(AF13="x","x",IF(AF13="-","-","")) -> - | DM13: - | DN13: - | DO13: - | DP13: -
A14: yes | B14: 13 | C14: TST013 | D14: red | E14: SLink | F14: 13 | J14: yes | K14: 10 | L14: yes | M14: 260 | N14: no | P14: - | Q14: - | R14: - | S14: - | T14: - | U14: - | V14: - | W14: - | Y14: x | AH14: yes | AI14: yes | AL14: x | BJ14: - | BK14: - | BL14: - | BM14: - | BN14: - | BO14: - | BP14: - | BQ14: - | BS14: =IF(AK14="x","x",IF(AK14="-","-","")) | BT14: =IF(AL14="x","x",IF(AL14="-","-","")) -> x | BU14: =IF(AM14="x","x",IF(AM14="-","-","")) | BV14: =IF(AN14="x","x",IF(AN14="-","-","")) | BW14: =IF(AO14="x","x",IF(AO14="-","-","")) | BX14: =IF(AP14="x","x",IF(AP14="-","-","")) | BY14: =IF(AQ14="x","x",IF(AQ14="-","-","")) | BZ14: =IF(AR14="x","x",IF(AR14="-","-","")) | ... CP14: =IF(BH14="x","x",IF(BH14="-","-","")) | CR14: =IF(P14="x","x",IF(P14="-","-","")) -> - | CS14: =IF(Q14="x","x",IF(Q14="-","-","")) -> - | CT14: =IF(R14="x","x",IF(R14="-","-","")) -> - | CU14: =IF(S14="x","x",IF(S14="-","-","")) -> - | CV14: =IF(T14="x","x",IF(T14="-","-","")) -> - | CW14: =IF(U14="x","x",IF(U14="-","-","")) -> - | CX14: =IF(V14="x","x",IF(V14="-","-","")) -> - | CY14: =IF(W14="x","x",IF(W14="-","-","")) -> - | CZ14: - | DA14: - | DB14: - | DC14: - | DE14: =IF(Y14="x","x",IF(Y14="-","-","")) -> x | DF14: =IF(Z14="x","x",IF(Z14="-","-","")) | DG14: =IF(AA14="x","x",IF(AA14="-","-","")) | DH14: =IF(AB14="x","x",IF(AB14="-","-","")) | DI14: =IF(AC14="x","x",IF(AC14="-","-","")) | DJ14: =IF(AD14="x","x",IF(AD14="-","-","")) | DK14: =IF(AE14="x","x",IF(AE14="-","-","")) | DL14: =IF(AF14="x","x",IF(AF14="-","-","")) | DM14: - | DN14: - | DO14: - | DP14: -
A15: yes | B15: 14 | C15: TST014 | D15: red | E15: SLink | F15: 14 | G15: - | H15: - | I15: - | J15: no | K15: 5 | L15: no | M15: 280 | N15: no | P15: - | Q15: - | R15: - | S15: - | T15: - | U15: - | V15: - | W15: - | Z15: x | AH15: yes | AI15: yes | AL15: x | BJ15: - | BK15: - | BL15: - | BM15: - | BN15: - | BO15: - | BP15: - | BQ15: - | BS15: =IF(AK15="x","x",IF(AK15="-","-","")) | BT15: =IF(AL15="x","x",IF(AL15="-","-","")) -> x | BU15: =IF(AM15="x","x",IF(AM15="-","-","")) | BV15: =IF(AN15="x","x",IF(AN15="-","-","")) | BW15: =IF(AO15="x","x",IF(AO15="-","-","")) | BX15: =IF(AP15="x","x",IF(AP15="-","-","")) | BY15: =IF(AQ15="x","x",IF(AQ15="-","-","")) | BZ15: =IF(AR15="x","x",IF(AR15="-","-","")) | ... CP15: =IF(BH15="x","x",IF(BH15="-","-","")) | CR15: =IF(P15="x","x",IF(P15="-","-","")) -> - | CS15: =IF(Q15="x","x",IF(Q15="-","-","")) -> - | CT15: =IF(R15="x","x",IF(R15="-","-","")) -> - | CU15: =IF(S15="x","x",IF(S15="-","-","")) -> - | CV15: =IF(T15="x","x",IF(T15="-","-","")) -> - | CW15: =IF(U15="x","x",IF(U15="-","-","")) -> - | CX15: =IF(V15="x","x",IF(V15="-","-","")) -> - | CY15: =IF(W15="x","x",IF(W15="-","-","")) -> - | CZ15: - | DA15: - | DB15: - | DC15: - | DE15: =IF(Y15="x","x",IF(Y15="-","-","")) | DF15: =IF(Z15="x","x",IF(Z15="-","-","")) -> x | DG15: =IF(AA15="x","x",IF(AA15="-","-","")) | DH15: =IF(AB15="x","x",IF(AB15="-","-","")) | DI15: =IF(AC15="x","x",IF(AC15="-","-","")) | DJ15: =IF(AD15="x","x",IF(AD15="-","-","")) | DK15: =IF(AE15="x","x",IF(AE15="-","-","")) | DL15: =IF(AF15="x","x",IF(AF15="-","-","")) | DM15: - | DN15: - | DO15: - | DP15: -
A16: yes | B16: 15 | C16: TST015 | D16: red | E16: SLink | F16: 15 | G16: 5 | H16: yes | I16: no | J16: yes | K16: 0 | L16: yes | M16: 300 | N16: no | P16: - | Q16: - | R16: - | S16: - | T16: - | U16: - | V16: - | W16: - | AA16: x | AH16: yes | AI16: yes | AL16: x | BJ16: - | BK16: - | BL16: - | BM16: - | BN16: - | BO16: - | BP16: - | BQ16: - | BS16: =IF(AK16="x","x",IF(AK16="-","-","")) | BT16: =IF(AL16="x","x",IF(AL16="-","-","")) -> x | BU16: =IF(AM16="x","x",IF(AM16="-","-","")) | BV16: =IF(AN16="x","x",IF(AN16="-","-","")) | BW16: =IF(AO16="x","x",IF(AO16="-","-","")) | BX16: =IF(AP16="x","x",IF(AP16="-","-","")) | BY16: =IF(AQ16="x","x",IF(AQ16="-","-","")) | BZ16: =IF(AR16="x","x",IF(AR16="-","-","")) | ... CP16: =IF(BH16="x","x",IF(BH16="-","-","")) | CR16: =IF(P16="x","x",IF(P16="-","-","")) -> - | CS16: =IF(Q16="x","x",IF(Q16="-","-","")) -> - | CT16: =IF(R16="x","x",IF(R16="-","-","")) -> - | CU16: =IF(S16="x","x",IF(S16="-","-","")) -> - | CV16: =IF(T16="x","x",IF(T16="-","-","")) -> - | CW16: =IF(U16="x","x",IF(U16="-","-","")) -> - | CX16: =IF(V16="x","x",IF(V16="-","-","")) -> - | CY16: =IF(W16="x","x",IF(W16="-","-","")) -> - | CZ16: - | DA16: - | DB16: - | DC16: - | DE16: =IF(Y16="x","x",IF(Y16="-","-","")) | DF16: =IF(Z16="x","x",IF(Z16="-","-","")) | DG16: =IF(AA16="x","x",IF(AA16="-","-","")) -> x | DH16: =IF(AB16="x","x",IF(AB16="-","-","")) | DI16: =IF(AC16="x","x",IF(AC16="-","-","")) | DJ16: =IF(AD16="x","x",IF(AD16="-","-","")) | DK16: =IF(AE16="x","x",IF(AE16="-","-","")) | DL16: =IF(AF16="x","x",IF(AF16="-","-","")) | DM16: - | DN16: - | DO16: - | DP16: -
A17: yes | B17: 16 | C17: TST016 | D17: red | E17: SLink | F17: 16 | G17: 10 | H17: no | I17: yes | J17: no | K17: -5 | L17: no | M17: 320 | N17: no | P17: - | Q17: - | R17: - | S17: - | T17: - | U17: - | V17: - | W17: - | AB17: x | AH17: yes | AI17: yes | AL17: x | BJ17: - | BK17: - | BL17: - | BM17: - | BN17: - | BO17: - | BP17: - | BQ17: - | BS17: =IF(AK17="x","x",IF(AK17="-","-","")) | BT17: =IF(AL17="x","x",IF(AL17="-","-","")) -> x | BU17: =IF(AM17="x","x",IF(AM17="-","-","")) | BV17: =IF(AN17="x","x",IF(AN17="-","-","")) | BW17: =IF(AO17="x","x",IF(AO17="-","-","")) | BX17: =IF(AP17="x","x",IF(AP17="-","-","")) | BY17: =IF(AQ17="x","x",IF(AQ17="-","-","")) | BZ17: =IF(AR17="x","x",IF(AR17="-","-","")) | ... CP17: =IF(BH17="x","x",IF(BH17="-","-","")) | CR17: =IF(P17="x","x",IF(P17="-","-","")) -> - | CS17: =IF(Q17="x","x",IF(Q17="-","-","")) -> - | CT17: =IF(R17="x","x",IF(R17="-","-","")) -> - | CU17: =IF(S17="x","x",IF(S17="-","-","")) -> - | CV17: =IF(T17="x","x",IF(T17="-","-","")) -> - | CW17: =IF(U17="x","x",IF(U17="-","-","")) -> - | CX17: =IF(V17="x","x",IF(V17="-","-","")) -> - | CY17: =IF(W17="x","x",IF(W17="-","-","")) -> - | CZ17: - | DA17: - | DB17: - | DC17: - | DE17: =IF(Y17="x","x",IF(Y17="-","-","")) | DF17: =IF(Z17="x","x",IF(Z17="-","-","")) | DG17: =IF(AA17="x","x",IF(AA17="-","-","")) | DH17: =IF(AB17="x","x",IF(AB17="-","-","")) -> x | DI17: =IF(AC17="x","x",IF(AC17="-","-","")) | DJ17: =IF(AD17="x","x",IF(AD17="-","-","")) | DK17: =IF(AE17="x","x",IF(AE17="-","-","")) | DL17: =IF(AF17="x","x",IF(AF17="-","-","")) | DM17: - | DN17: - | DO17: - | DP17: -
A18: yes | B18: 17 | C18: TST017 | D18: red | E18: SLink | F18: 17 | G18: 15 | H18: yes | I18: no | J18: yes | K18: -10 | L18: yes | M18: 340 | N18: no | P18: - | Q18: - | R18: - | S18: - | T18: - | U18: - | V18: - | W18: - | AC18: x | AH18: yes | AI18: yes | AL18: x | BJ18: - | BK18: - | BL18: - | BM18: - | BN18: - | BO18: - | BP18: - | BQ18: - | BS18: =IF(AK18="x","x",IF(AK18="-","-","")) | BT18: =IF(AL18="x","x",IF(AL18="-","-","")) -> x | BU18: =IF(AM18="x","x",IF(AM18="-","-","")) | BV18: =IF(AN18="x","x",IF(AN18="-","-","")) | BW18: =IF(AO18="x","x",IF(AO18="-","-","")) | BX18: =IF(AP18="x","x",IF(AP18="-","-","")) | BY18: =IF(AQ18="x","x",IF(AQ18="-","-","")) | BZ18: =IF(AR18="x","x",IF(AR18="-","-","")) | ... CP18: =IF(BH18="x","x",IF(BH18="-","-","")) | CR18: =IF(P18="x","x",IF(P18="-","-","")) -> - | CS18: =IF(Q18="x","x",IF(Q18="-","-","")) -> - | CT18: =IF(R18="x","x",IF(R18="-","-","")) -> - | CU18: =IF(S18="x","x",IF(S18="-","-","")) -> - | CV18: =IF(T18="x","x",IF(T18="-","-","")) -> - | CW18: =IF(U18="x","x",IF(U18="-","-","")) -> - | CX18: =IF(V18="x","x",IF(V18="-","-","")) -> - | CY18: =IF(W18="x","x",IF(W18="-","-","")) -> - | CZ18: - | DA18: - | DB18: - | DC18: - | DE18: =IF(Y18="x","x",IF(Y18="-","-","")) | DF18: =IF(Z18="x","x",IF(Z18="-","-","")) | DG18: =IF(AA18="x","x",IF(AA18="-","-","")) | DH18: =IF(AB18="x","x",IF(AB18="-","-","")) | DI18: =IF(AC18="x","x",IF(AC18="-","-","")) -> x | DJ18: =IF(AD18="x","x",IF(AD18="-","-","")) | DK18: =IF(AE18="x","x",IF(AE18="-","-","")) | DL18: =IF(AF18="x","x",IF(AF18="-","-","")) | DM18: - | DN18: - | DO18: - | DP18: -
A19: yes | B19: 18 | C19: TST018 | D19: red | E19: SLink | F19: 18 | G19: 20 | H19: no | I19: yes | J19: no | K19: -15 | L19: no | M19: 360 | N19: no | P19: - | Q19: - | R19: - | S19: - | T19: - | U19: - | V19: - | W19: - | AD19: x | AH19: yes | AI19: yes | AL19: x | BJ19: - | BK19: - | BL19: - | BM19: - | BN19: - | BO19: - | BP19: - | BQ19: - | BS19: =IF(AK19="x","x",IF(AK19="-","-","")) | BT19: =IF(AL19="x","x",IF(AL19="-","-","")) -> x | BU19: =IF(AM19="x","x",IF(AM19="-","-","")) | BV19: =IF(AN19="x","x",IF(AN19="-","-","")) | BW19: =IF(AO19="x","x",IF(AO19="-","-","")) | BX19: =IF(AP19="x","x",IF(AP19="-","-","")) | BY19: =IF(AQ19="x","x",IF(AQ19="-","-","")) | BZ19: =IF(AR19="x","x",IF(AR19="-","-","")) | ... CP19: =IF(BH19="x","x",IF(BH19="-","-","")) | CR19: =IF(P19="x","x",IF(P19="-","-","")) -> - | CS19: =IF(Q19="x","x",IF(Q19="-","-","")) -> - | CT19: =IF(R19="x","x",IF(R19="-","-","")) -> - | CU19: =IF(S19="x","x",IF(S19="-","-","")) -> - | CV19: =IF(T19="x","x",IF(T19="-","-","")) -> - | CW19: =IF(U19="x","x",IF(U19="-","-","")) -> - | CX19: =IF(V19="x","x",IF(V19="-","-","")) -> - | CY19: =IF(W19="x","x",IF(W19="-","-","")) -> - | CZ19: - | DA19: - | DB19: - | DC19: - | DE19: =IF(Y19="x","x",IF(Y19="-","-","")) | DF19: =IF(Z19="x","x",IF(Z19="-","-","")) | DG19: =IF(AA19="x","x",IF(AA19="-","-","")) | DH19: =IF(AB19="x","x",IF(AB19="-","-","")) | DI19: =IF(AC19="x","x",IF(AC19="-","-","")) | DJ19: =IF(AD19="x","x",IF(AD19="-","-","")) -> x | DK19: =IF(AE19="x","x",IF(AE19="-","-","")) | DL19: =IF(AF19="x","x",IF(AF19="-","-","")) | DM19: - | DN19: - | DO19: - | DP19: -
A20: yes | B20: 19 | C20: TST019 | D20: red | E20: SLink | F20: 19 | G20: 25 | H20: yes | I20: no | J20: yes | K20: -20 | L20: yes | M20: 380 | N20: no | P20: - | Q20: - | R20: - | S20: - | T20: - | U20: - | V20: - | W20: - | AE20: x | AH20: yes | AI20: yes | AL20: x | BJ20: - | BK20: - | BL20: - | BM20: - | BN20: - | BO20: - | BP20: - | BQ20: - | BS20: =IF(AK20="x","x",IF(AK20="-","-","")) | BT20: =IF(AL20="x","x",IF(AL20="-","-","")) -> x | BU20: =IF(AM20="x","x",IF(AM20="-","-","")) | BV20: =IF(AN20="x","x",IF(AN20="-","-","")) | BW20: =IF(AO20="x","x",IF(AO20="-","-","")) | BX20: =IF(AP20="x","x",IF(AP20="-","-","")) | BY20: =IF(AQ20="x","x",IF(AQ20="-","-","")) | BZ20: =IF(AR20="x","x",IF(AR20="-","-","")) | ... CP20: =IF(BH20="x","x",IF(BH20="-","-","")) | CR20: =IF(P20="x","x",IF(P20="-","-","")) -> - | CS20: =IF(Q20="x","x",IF(Q20="-","-","")) -> - | CT20: =IF(R20="x","x",IF(R20="-","-","")) -> - | CU20: =IF(S20="x","x",IF(S20="-","-","")) -> - | CV20: =IF(T20="x","x",IF(T20="-","-","")) -> - | CW20: =IF(U20="x","x",IF(U20="-","-","")) -> - | CX20: =IF(V20="x","x",IF(V20="-","-","")) -> - | CY20: =IF(W20="x","x",IF(W20="-","-","")) -> - | CZ20: - | DA20: - | DB20: - | DC20: - | DE20: =IF(Y20="x","x",IF(Y20="-","-","")) | DF20: =IF(Z20="x","x",IF(Z20="-","-","")) | DG20: =IF(AA20="x","x",IF(AA20="-","-","")) | DH20: =IF(AB20="x","x",IF(AB20="-","-","")) | DI20: =IF(AC20="x","x",IF(AC20="-","-","")) | DJ20: =IF(AD20="x","x",IF(AD20="-","-","")) | DK20: =IF(AE20="x","x",IF(AE20="-","-","")) -> x | DL20: =IF(AF20="x","x",IF(AF20="-","-","")) | DM20: - | DN20: - | DO20: - | DP20: -
A21: yes | B21: 20 | C21: TST020 | D21: red | E21: SLink | F21: 20 | G21: 30 | H21: no | I21: yes | J21: no | K21: -25 | L21: no | M21: 400 | N21: no | P21: - | Q21: - | R21: - | S21: - | T21: - | U21: - | V21: - | W21: - | AF21: x | AH21: yes | AI21: yes | AL21: x | BJ21: - | BK21: - | BL21: - | BM21: - | BN21: - | BO21: - | BP21: - | BQ21: - | BS21: =IF(AK21="x","x",IF(AK21="-","-","")) | BT21: =IF(AL21="x","x",IF(AL21="-","-","")) -> x | BU21: =IF(AM21="x","x",IF(AM21="-","-","")) | BV21: =IF(AN21="x","x",IF(AN21="-","-","")) | BW21: =IF(AO21="x","x",IF(AO21="-","-","")) | BX21: =IF(AP21="x","x",IF(AP21="-","-","")) | BY21: =IF(AQ21="x","x",IF(AQ21="-","-","")) | BZ21: =IF(AR21="x","x",IF(AR21="-","-","")) | ... CP21: =IF(BH21="x","x",IF(BH21="-","-","")) | CR21: =IF(P21="x","x",IF(P21="-","-","")) -> - | CS21: =IF(Q21="x","x",IF(Q21="-","-","")) -> - | CT21: =IF(R21="x","x",IF(R21="-","-","")) -> - | CU21: =IF(S21="x","x",IF(S21="-","-","")) -> - | CV21: =IF(T21="x","x",IF(T21="-","-","")) -> - | CW21: =IF(U21="x","x",IF(U21="-","-","")) -> - | CX21: =IF(V21="x","x",IF(V21="-","-","")) -> - | CY21: =IF(W21="x","x",IF(W21="-","-","")) -> - | CZ21: - | DA21: - | DB21: - | DC21: - | DE21: =IF(Y21="x","x",IF(Y21="-","-","")) | DF21: =IF(Z21="x","x",IF(Z21="-","-","")) | DG21: =IF(AA21="x","x",IF(AA21="-","-","")) | DH21: =IF(AB21="x","x",IF(AB21="-","-","")) | DI21: =IF(AC21="x","x",IF(AC21="-","-","")) | DJ21: =IF(AD21="x","x",IF(AD21="-","-","")) | DK21: =IF(AE21="x","x",IF(AE21="-","-","")) | DL21: =IF(AF21="x","x",IF(AF21="-","-","")) -> x | DM21: - | DN21: - | DO21: - | DP21: -
A22: yes | B22: 21 | C22: TST021 | D22: red | E22: SLink | F22: 21 | G22: 35 | H22: yes | I22: no | J22: yes | K22: -30 | L22: yes | M22: 420 | N22: no | P22: - | Q22: - | R22: - | S22: - | T22: - | U22: - | V22: - | W22: - | Y22: - | Z22: - | AA22: - | AB22: - | AC22: - | AD22: - | AE22: - | AF22: - | AH22: yes | AI22: yes | AL22: x | BJ22: - | BK22: - | BL22: - | BM22: - | BN22: - | BO22: - | BP22: - | BQ22: - | BS22: =IF(AK22="x","x",IF(AK22="-","-","")) | BT22: =IF(AL22="x","x",IF(AL22="-","-","")) -> x | BU22: =IF(AM22="x","x",IF(AM22="-","-","")) | BV22: =IF(AN22="x","x",IF(AN22="-","-","")) | BW22: =IF(AO22="x","x",IF(AO22="-","-","")) | BX22: =IF(AP22="x","x",IF(AP22="-","-","")) | BY22: =IF(AQ22="x","x",IF(AQ22="-","-","")) | BZ22: =IF(AR22="x","x",IF(AR22="-","-","")) | ... CP22: =IF(BH22="x","x",IF(BH22="-","-","")) | CR22: =IF(P22="x","x",IF(P22="-","-","")) -> - | CS22: =IF(Q22="x","x",IF(Q22="-","-","")) -> - | CT22: =IF(R22="x","x",IF(R22="-","-","")) -> - | CU22: =IF(S22="x","x",IF(S22="-","-","")) -> - | CV22: =IF(T22="x","x",IF(T22="-","-","")) -> - | CW22: =IF(U22="x","x",IF(U22="-","-","")) -> - | CX22: =IF(V22="x","x",IF(V22="-","-","")) -> - | CY22: =IF(W22="x","x",IF(W22="-","-","")) -> - | CZ22: - | DA22: - | DB22: - | DC22: - | DE22: =IF(Y22="x","x",IF(Y22="-","-","")) -> - | DF22: =IF(Z22="x","x",IF(Z22="-","-","")) -> - | DG22: =IF(AA22="x","x",IF(AA22="-","-","")) -> - | DH22: =IF(AB22="x","x",IF(AB22="-","-","")) -> - | DI22: =IF(AC22="x","x",IF(AC22="-","-","")) -> - | DJ22: =IF(AD22="x","x",IF(AD22="-","-","")) -> - | DK22: =IF(AE22="x","x",IF(AE22="-","-","")) -> - | DL22: =IF(AF22="x","x",IF(AF22="-","-","")) -> - | DM22: - | DN22: - | DO22: - | DP22: -
A23: yes | B23: 22 | C23: TST022 | D23: red | E23: SLink | F23: 22 | G23: 40 | H23: no | I23: yes | J23: no | K23: -35 | L23: no | M23: 440 | N23: no | P23: - | Q23: - | R23: - | S23: - | T23: - | U23: - | V23: - | W23: - | Y23: - | Z23: - | AA23: - | AB23: - | AC23: - | AD23: - | AE23: - | AF23: - | AH23: yes | AI23: yes | AL23: x | BJ23: - | BK23: - | BL23: - | BM23: - | BN23: - | BO23: - | BP23: - | BQ23: - | BS23: =IF(AK23="x","x",IF(AK23="-","-","")) | BT23: =IF(AL23="x","x",IF(AL23="-","-","")) -> x | BU23: =IF(AM23="x","x",IF(AM23="-","-","")) | BV23: =IF(AN23="x","x",IF(AN23="-","-","")) | BW23: =IF(AO23="x","x",IF(AO23="-","-","")) | BX23: =IF(AP23="x","x",IF(AP23="-","-","")) | BY23: =IF(AQ23="x","x",IF(AQ23="-","-","")) | BZ23: =IF(AR23="x","x",IF(AR23="-","-","")) | ... CP23: =IF(BH23="x","x",IF(BH23="-","-","")) | CR23: =IF(P23="x","x",IF(P23="-","-","")) -> - | CS23: =IF(Q23="x","x",IF(Q23="-","-","")) -> - | CT23: =IF(R23="x","x",IF(R23="-","-","")) -> - | CU23: =IF(S23="x","x",IF(S23="-","-","")) -> - | CV23: =IF(T23="x","x",IF(T23="-","-","")) -> - | CW23: =IF(U23="x","x",IF(U23="-","-","")) -> - | CX23: =IF(V23="x","x",IF(V23="-","-","")) -> - | CY23: =IF(W23="x","x",IF(W23="-","-","")) -> - | CZ23: - | DA23: - | DB23: - | DC23: - | DE23: =IF(Y23="x","x",IF(Y23="-","-","")) -> - | DF23: =IF(Z23="x","x",IF(Z23="-","-","")) -> - | DG23: =IF(AA23="x","x",IF(AA23="-","-","")) -> - | DH23: =IF(AB23="x","x",IF(AB23="-","-","")) -> - | DI23: =IF(AC23="x","x",IF(AC23="-","-","")) -> - | DJ23: =IF(AD23="x","x",IF(AD23="-","-","")) -> - | DK23: =IF(AE23="x","x",IF(AE23="-","-","")) -> - | DL23: =IF(AF23="x","x",IF(AF23="-","-","")) -> - | DM23: - | DN23: - | DO23: - | DP23: -
A24: yes | B24: 23 | C24: TST023 | D24: red | E24: SLink | F24: 23 | G24: 45 | H24: yes | I24: no | J24: yes | K24: -40 | L24: yes | M24: 460 | N24: no | P24: - | Q24: - | R24: - | S24: - | T24: - | U24: - | V24: - | W24: - | Y24: - | Z24: - | AA24: - | AB24: - | AC24: - | AD24: - | AE24: - | AF24: - | AH24: yes | AI24: yes | AL24: x | BJ24: - | BK24: - | BL24: - | BM24: - | BN24: - | BO24: - | BP24: - | BQ24: - | BS24: =IF(AK24="x","x",IF(AK24="-","-","")) | BT24: =IF(AL24="x","x",IF(AL24="-","-","")) -> x | BU24: =IF(AM24="x","x",IF(AM24="-","-","")) | BV24: =IF(AN24="x","x",IF(AN24="-","-","")) | BW24: =IF(AO24="x","x",IF(AO24="-","-","")) | BX24: =IF(AP24="x","x",IF(AP24="-","-","")) | BY24: =IF(AQ24="x","x",IF(AQ24="-","-","")) | BZ24: =IF(AR24="x","x",IF(AR24="-","-","")) | ... CP24: =IF(BH24="x","x",IF(BH24="-","-","")) | CR24: =IF(P24="x","x",IF(P24="-","-","")) -> - | CS24: =IF(Q24="x","x",IF(Q24="-","-","")) -> - | CT24: =IF(R24="x","x",IF(R24="-","-","")) -> - | CU24: =IF(S24="x","x",IF(S24="-","-","")) -> - | CV24: =IF(T24="x","x",IF(T24="-","-","")) -> - | CW24: =IF(U24="x","x",IF(U24="-","-","")) -> - | CX24: =IF(V24="x","x",IF(V24="-","-","")) -> - | CY24: =IF(W24="x","x",IF(W24="-","-","")) -> - | CZ24: - | DA24: - | DB24: - | DC24: - | DE24: =IF(Y24="x","x",IF(Y24="-","-","")) -> - | DF24: =IF(Z24="x","x",IF(Z24="-","-","")) -> - | DG24: =IF(AA24="x","x",IF(AA24="-","-","")) -> - | DH24: =IF(AB24="x","x",IF(AB24="-","-","")) -> - | DI24: =IF(AC24="x","x",IF(AC24="-","-","")) -> - | DJ24: =IF(AD24="x","x",IF(AD24="-","-","")) -> - | DK24: =IF(AE24="x","x",IF(AE24="-","-","")) -> - | DL24: =IF(AF24="x","x",IF(AF24="-","-","")) -> - | DM24: - | DN24: - | DO24: - | DP24: -
A25: yes | B25: 24 | C25: TST024 | D25: red | E25: SLink | F25: 24 | G25: 50 | H25: no | I25: yes | J25: no | K25: -45 | L25: no | M25: 480 | N25: no | P25: - | Q25: - | R25: - | S25: - | T25: - | U25: - | V25: - | W25: - | Y25: - | Z25: - | AA25: - | AB25: - | AC25: - | AD25: - | AE25: - | AF25: - | AH25: yes | AI25: yes | AL25: x | BJ25: - | BK25: - | BL25: - | BM25: - | BN25: - | BO25: - | BP25: - | BQ25: - | BS25: =IF(AK25="x","x",IF(AK25="-","-","")) | BT25: =IF(AL25="x","x",IF(AL25="-","-","")) -> x | BU25: =IF(AM25="x","x",IF(AM25="-","-","")) | BV25: =IF(AN25="x","x",IF(AN25="-","-","")) | BW25: =IF(AO25="x","x",IF(AO25="-","-","")) | BX25: =IF(AP25="x","x",IF(AP25="-","-","")) | BY25: =IF(AQ25="x","x",IF(AQ25="-","-","")) | BZ25: =IF(AR25="x","x",IF(AR25="-","-","")) | ... CP25: =IF(BH25="x","x",IF(BH25="-","-","")) | CR25: =IF(P25="x","x",IF(P25="-","-","")) -> - | CS25: =IF(Q25="x","x",IF(Q25="-","-","")) -> - | CT25: =IF(R25="x","x",IF(R25="-","-","")) -> - | CU25: =IF(S25="x","x",IF(S25="-","-","")) -> - | CV25: =IF(T25="x","x",IF(T25="-","-","")) -> - | CW25: =IF(U25="x","x",IF(U25="-","-","")) -> - | CX25: =IF(V25="x","x",IF(V25="-","-","")) -> - | CY25: =IF(W25="x","x",IF(W25="-","-","")) -> - | CZ25: - | DA25: - | DB25: - | DC25: - | DE25: =IF(Y25="x","x",IF(Y25="-","-","")) -> - | DF25: =IF(Z25="x","x",IF(Z25="-","-","")) -> - | DG25: =IF(AA25="x","x",IF(AA25="-","-","")) -> - | DH25: =IF(AB25="x","x",IF(AB25="-","-","")) -> - | DI25: =IF(AC25="x","x",IF(AC25="-","-","")) -> - | DJ25: =IF(AD25="x","x",IF(AD25="-","-","")) -> - | DK25: =IF(AE25="x","x",IF(AE25="-","-","")) -> - | DL25: =IF(AF25="x","x",IF(AF25="-","-","")) -> - | DM25: - | DN25: - | DO25: - | DP25: -
A26: yes | B26: 25 | C26: TST025 | D26: yellow | E26: SLink | F26: 25 | G26: 55 | H26: yes | I26: no | J26: yes | K26: -99 | L26: yes | M26: 500 | N26: - | P26: - | Q26: - | R26: - | S26: - | T26: - | U26: - | V26: - | W26: - | Y26: - | Z26: - | AA26: - | AB26: - | AC26: - | AD26: - | AE26: - | AF26: - | AH26: yes | AI26: yes | AM26: x | BJ26: - | BK26: - | BL26: - | BM26: - | BN26: - | BO26: - | BP26: - | BQ26: - | BS26: =IF(AK26="x","x",IF(AK26="-","-","")) | BT26: =IF(AL26="x","x",IF(AL26="-","-","")) | BU26: =IF(AM26="x","x",IF(AM26="-","-","")) -> x | BV26: =IF(AN26="x","x",IF(AN26="-","-","")) | BW26: =IF(AO26="x","x",IF(AO26="-","-","")) | BX26: =IF(AP26="x","x",IF(AP26="-","-","")) | BY26: =IF(AQ26="x","x",IF(AQ26="-","-","")) | BZ26: =IF(AR26="x","x",IF(AR26="-","-","")) | ... CP26: =IF(BH26="x","x",IF(BH26="-","-","")) | CR26: =IF(P26="x","x",IF(P26="-","-","")) -> - | CS26: =IF(Q26="x","x",IF(Q26="-","-","")) -> - | CT26: =IF(R26="x","x",IF(R26="-","-","")) -> - | CU26: =IF(S26="x","x",IF(S26="-","-","")) -> - | CV26: =IF(T26="x","x",IF(T26="-","-","")) -> - | CW26: =IF(U26="x","x",IF(U26="-","-","")) -> - | CX26: =IF(V26="x","x",IF(V26="-","-","")) -> - | CY26: =IF(W26="x","x",IF(W26="-","-","")) -> - | CZ26: - | DA26: - | DB26: - | DC26: - | DE26: =IF(Y26="x","x",IF(Y26="-","-","")) -> - | DF26: =IF(Z26="x","x",IF(Z26="-","-","")) -> - | DG26: =IF(AA26="x","x",IF(AA26="-","-","")) -> - | DH26: =IF(AB26="x","x",IF(AB26="-","-","")) -> - | DI26: =IF(AC26="x","x",IF(AC26="-","-","")) -> - | DJ26: =IF(AD26="x","x",IF(AD26="-","-","")) -> - | DK26: =IF(AE26="x","x",IF(AE26="-","-","")) -> - | DL26: =IF(AF26="x","x",IF(AF26="-","-","")) -> - | DM26: - | DN26: - | DO26: - | DP26: -
A27: yes | B27: 26 | C27: TST026 | D27: yellow | E27: SLink | F27: 26 | G27: 60 | H27: no | I27: yes | J27: no | K27: 10 | L27: no | M27: 520 | N27: - | P27: - | Q27: - | R27: - | S27: - | T27: - | U27: - | V27: - | W27: - | Y27: - | Z27: - | AA27: - | AB27: - | AC27: - | AD27: - | AE27: - | AF27: - | AH27: yes | AI27: yes | AM27: x | BJ27: - | BK27: - | BL27: - | BM27: - | BN27: - | BO27: - | BP27: - | BQ27: - | BS27: =IF(AK27="x","x",IF(AK27="-","-","")) | BT27: =IF(AL27="x","x",IF(AL27="-","-","")) | BU27: =IF(AM27="x","x",IF(AM27="-","-","")) -> x | BV27: =IF(AN27="x","x",IF(AN27="-","-","")) | BW27: =IF(AO27="x","x",IF(AO27="-","-","")) | BX27: =IF(AP27="x","x",IF(AP27="-","-","")) | BY27: =IF(AQ27="x","x",IF(AQ27="-","-","")) | BZ27: =IF(AR27="x","x",IF(AR27="-","-","")) | ... CP27: =IF(BH27="x","x",IF(BH27="-","-","")) | CR27: =IF(P27="x","x",IF(P27="-","-","")) -> - | CS27: =IF(Q27="x","x",IF(Q27="-","-","")) -> - | CT27: =IF(R27="x","x",IF(R27="-","-","")) -> - | CU27: =IF(S27="x","x",IF(S27="-","-","")) -> - | CV27: =IF(T27="x","x",IF(T27="-","-","")) -> - | CW27: =IF(U27="x","x",IF(U27="-","-","")) -> - | CX27: =IF(V27="x","x",IF(V27="-","-","")) -> - | CY27: =IF(W27="x","x",IF(W27="-","-","")) -> - | CZ27: - | DA27: - | DB27: - | DC27: - | DE27: =IF(Y27="x","x",IF(Y27="-","-","")) -> - | DF27: =IF(Z27="x","x",IF(Z27="-","-","")) -> - | DG27: =IF(AA27="x","x",IF(AA27="-","-","")) -> - | DH27: =IF(AB27="x","x",IF(AB27="-","-","")) -> - | DI27: =IF(AC27="x","x",IF(AC27="-","-","")) -> - | DJ27: =IF(AD27="x","x",IF(AD27="-","-","")) -> - | DK27: =IF(AE27="x","x",IF(AE27="-","-","")) -> - | DL27: =IF(AF27="x","x",IF(AF27="-","-","")) -> - | DM27: - | DN27: - | DO27: - | DP27: -
A28: yes | B28: 27 | C28: TST027 | D28: yellow | E28: SLink | F28: 27 | G28: - | H28: - | I28: - | J28: yes | K28: 5 | L28: yes | M28: 540 | N28: - | P28: - | Q28: - | R28: - | S28: - | T28: - | U28: - | V28: - | W28: - | Y28: - | Z28: - | AA28: - | AB28: - | AC28: - | AD28: - | AE28: - | AF28: - | AH28: yes | AI28: yes | AM28: x | BJ28: - | BK28: - | BL28: - | BM28: - | BN28: - | BO28: - | BP28: - | BQ28: - | BS28: =IF(AK28="x","x",IF(AK28="-","-","")) | BT28: =IF(AL28="x","x",IF(AL28="-","-","")) | BU28: =IF(AM28="x","x",IF(AM28="-","-","")) -> x | BV28: =IF(AN28="x","x",IF(AN28="-","-","")) | BW28: =IF(AO28="x","x",IF(AO28="-","-","")) | BX28: =IF(AP28="x","x",IF(AP28="-","-","")) | BY28: =IF(AQ28="x","x",IF(AQ28="-","-","")) | BZ28: =IF(AR28="x","x",IF(AR28="-","-","")) | ... CP28: =IF(BH28="x","x",IF(BH28="-","-","")) | CR28: =IF(P28="x","x",IF(P28="-","-","")) -> - | CS28: =IF(Q28="x","x",IF(Q28="-","-","")) -> - | CT28: =IF(R28="x","x",IF(R28="-","-","")) -> - | CU28: =IF(S28="x","x",IF(S28="-","-","")) -> - | CV28: =IF(T28="x","x",IF(T28="-","-","")) -> - | CW28: =IF(U28="x","x",IF(U28="-","-","")) -> - | CX28: =IF(V28="x","x",IF(V28="-","-","")) -> - | CY28: =IF(W28="x","x",IF(W28="-","-","")) -> - | CZ28: - | DA28: - | DB28: - | DC28: - | DE28: =IF(Y28="x","x",IF(Y28="-","-","")) -> - | DF28: =IF(Z28="x","x",IF(Z28="-","-","")) -> - | DG28: =IF(AA28="x","x",IF(AA28="-","-","")) -> - | DH28: =IF(AB28="x","x",IF(AB28="-","-","")) -> - | DI28: =IF(AC28="x","x",IF(AC28="-","-","")) -> - | DJ28: =IF(AD28="x","x",IF(AD28="-","-","")) -> - | DK28: =IF(AE28="x","x",IF(AE28="-","-","")) -> - | DL28: =IF(AF28="x","x",IF(AF28="-","-","")) -> - | DM28: - | DN28: - | DO28: - | DP28: -
A29: yes | B29: 28 | C29: TST028 | D29: yellow | E29: SLink | F29: 28 | G29: - | H29: - | I29: - | J29: no | K29: 0 | L29: no | M29: 560 | N29: - | P29: - | Q29: - | R29: - | S29: - | T29: - | U29: - | V29: - | W29: - | Y29: - | Z29: - | AA29: - | AB29: - | AC29: - | AD29: - | AE29: - | AF29: - | AH29: yes | AI29: yes | AM29: x | BJ29: - | BK29: - | BL29: - | BM29: - | BN29: - | BO29: - | BP29: - | BQ29: - | BS29: =IF(AK29="x","x",IF(AK29="-","-","")) | BT29: =IF(AL29="x","x",IF(AL29="-","-","")) | BU29: =IF(AM29="x","x",IF(AM29="-","-","")) -> x | BV29: =IF(AN29="x","x",IF(AN29="-","-","")) | BW29: =IF(AO29="x","x",IF(AO29="-","-","")) | BX29: =IF(AP29="x","x",IF(AP29="-","-","")) | BY29: =IF(AQ29="x","x",IF(AQ29="-","-","")) | BZ29: =IF(AR29="x","x",IF(AR29="-","-","")) | ... CP29: =IF(BH29="x","x",IF(BH29="-","-","")) | CR29: =IF(P29="x","x",IF(P29="-","-","")) -> - | CS29: =IF(Q29="x","x",IF(Q29="-","-","")) -> - | CT29: =IF(R29="x","x",IF(R29="-","-","")) -> - | CU29: =IF(S29="x","x",IF(S29="-","-","")) -> - | CV29: =IF(T29="x","x",IF(T29="-","-","")) -> - | CW29: =IF(U29="x","x",IF(U29="-","-","")) -> - | CX29: =IF(V29="x","x",IF(V29="-","-","")) -> - | CY29: =IF(W29="x","x",IF(W29="-","-","")) -> - | CZ29: - | DA29: - | DB29: - | DC29: - | DE29: =IF(Y29="x","x",IF(Y29="-","-","")) -> - | DF29: =IF(Z29="x","x",IF(Z29="-","-","")) -> - | DG29: =IF(AA29="x","x",IF(AA29="-","-","")) -> - | DH29: =IF(AB29="x","x",IF(AB29="-","-","")) -> - | DI29: =IF(AC29="x","x",IF(AC29="-","-","")) -> - | DJ29: =IF(AD29="x","x",IF(AD29="-","-","")) -> - | DK29: =IF(AE29="x","x",IF(AE29="-","-","")) -> - | DL29: =IF(AF29="x","x",IF(AF29="-","-","")) -> - | DM29: - | DN29: - | DO29: - | DP29: -
A30: yes | B30: 29 | C30: TST029 | D30: yellow | E30: SLink | F30: 29 | G30: - | H30: - | I30: - | J30: yes | K30: -5 | L30: yes | M30: 580 | N30: - | P30: - | Q30: - | R30: - | S30: - | T30: - | U30: - | V30: - | W30: - | Y30: - | Z30: - | AA30: - | AB30: - | AC30: - | AD30: - | AE30: - | AF30: - | AH30: yes | AI30: yes | AM30: x | BJ30: - | BK30: - | BL30: - | BM30: - | BN30: - | BO30: - | BP30: - | BQ30: - | BS30: =IF(AK30="x","x",IF(AK30="-","-","")) | BT30: =IF(AL30="x","x",IF(AL30="-","-","")) | BU30: =IF(AM30="x","x",IF(AM30="-","-","")) -> x | BV30: =IF(AN30="x","x",IF(AN30="-","-","")) | BW30: =IF(AO30="x","x",IF(AO30="-","-","")) | BX30: =IF(AP30="x","x",IF(AP30="-","-","")) | BY30: =IF(AQ30="x","x",IF(AQ30="-","-","")) | BZ30: =IF(AR30="x","x",IF(AR30="-","-","")) | ... CP30: =IF(BH30="x","x",IF(BH30="-","-","")) | CR30: =IF(P30="x","x",IF(P30="-","-","")) -> - | CS30: =IF(Q30="x","x",IF(Q30="-","-","")) -> - | CT30: =IF(R30="x","x",IF(R30="-","-","")) -> - | CU30: =IF(S30="x","x",IF(S30="-","-","")) -> - | CV30: =IF(T30="x","x",IF(T30="-","-","")) -> - | CW30: =IF(U30="x","x",IF(U30="-","-","")) -> - | CX30: =IF(V30="x","x",IF(V30="-","-","")) -> - | CY30: =IF(W30="x","x",IF(W30="-","-","")) -> - | CZ30: - | DA30: - | DB30: - | DC30: - | DE30: =IF(Y30="x","x",IF(Y30="-","-","")) -> - | DF30: =IF(Z30="x","x",IF(Z30="-","-","")) -> - | DG30: =IF(AA30="x","x",IF(AA30="-","-","")) -> - | DH30: =IF(AB30="x","x",IF(AB30="-","-","")) -> - | DI30: =IF(AC30="x","x",IF(AC30="-","-","")) -> - | DJ30: =IF(AD30="x","x",IF(AD30="-","-","")) -> - | DK30: =IF(AE30="x","x",IF(AE30="-","-","")) -> - | DL30: =IF(AF30="x","x",IF(AF30="-","-","")) -> - | DM30: - | DN30: - | DO30: - | DP30: -
A31: yes | B31: 30 | C31: TST030 | D31: yellow | E31: SLink | F31: 30 | G31: - | H31: - | I31: - | J31: no | K31: -10 | L31: no | M31: 600 | N31: - | P31: - | Q31: - | R31: - | S31: - | T31: - | U31: - | V31: - | W31: - | Y31: - | Z31: - | AA31: - | AB31: - | AC31: - | AD31: - | AE31: - | AF31: - | AH31: yes | AI31: yes | AM31: x | BJ31: - | BK31: - | BL31: - | BM31: - | BN31: - | BO31: - | BP31: - | BQ31: - | BS31: =IF(AK31="x","x",IF(AK31="-","-","")) | BT31: =IF(AL31="x","x",IF(AL31="-","-","")) | BU31: =IF(AM31="x","x",IF(AM31="-","-","")) -> x | BV31: =IF(AN31="x","x",IF(AN31="-","-","")) | BW31: =IF(AO31="x","x",IF(AO31="-","-","")) | BX31: =IF(AP31="x","x",IF(AP31="-","-","")) | BY31: =IF(AQ31="x","x",IF(AQ31="-","-","")) | BZ31: =IF(AR31="x","x",IF(AR31="-","-","")) | ... CP31: =IF(BH31="x","x",IF(BH31="-","-","")) | CR31: =IF(P31="x","x",IF(P31="-","-","")) -> - | CS31: =IF(Q31="x","x",IF(Q31="-","-","")) -> - | CT31: =IF(R31="x","x",IF(R31="-","-","")) -> - | CU31: =IF(S31="x","x",IF(S31="-","-","")) -> - | CV31: =IF(T31="x","x",IF(T31="-","-","")) -> - | CW31: =IF(U31="x","x",IF(U31="-","-","")) -> - | CX31: =IF(V31="x","x",IF(V31="-","-","")) -> - | CY31: =IF(W31="x","x",IF(W31="-","-","")) -> - | CZ31: - | DA31: - | DB31: - | DC31: - | DE31: =IF(Y31="x","x",IF(Y31="-","-","")) -> - | DF31: =IF(Z31="x","x",IF(Z31="-","-","")) -> - | DG31: =IF(AA31="x","x",IF(AA31="-","-","")) -> - | DH31: =IF(AB31="x","x",IF(AB31="-","-","")) -> - | DI31: =IF(AC31="x","x",IF(AC31="-","-","")) -> - | DJ31: =IF(AD31="x","x",IF(AD31="-","-","")) -> - | DK31: =IF(AE31="x","x",IF(AE31="-","-","")) -> - | DL31: =IF(AF31="x","x",IF(AF31="-","-","")) -> - | DM31: - | DN31: - | DO31: - | DP31: -
A32: yes | B32: 31 | C32: TST031 | D32: yellow | E32: SLink | F32: 31 | G32: - | H32: - | I32: - | J32: yes | K32: -15 | L32: yes | M32: 620 | N32: - | P32: - | Q32: - | R32: - | S32: - | T32: - | U32: - | V32: - | W32: - | Y32: - | Z32: - | AA32: - | AB32: - | AC32: - | AD32: - | AE32: - | AF32: - | AH32: yes | AI32: yes | AM32: x | BJ32: - | BK32: - | BL32: - | BM32: - | BN32: - | BO32: - | BP32: - | BQ32: - | BS32: =IF(AK32="x","x",IF(AK32="-","-","")) | BT32: =IF(AL32="x","x",IF(AL32="-","-","")) | BU32: =IF(AM32="x","x",IF(AM32="-","-","")) -> x | BV32: =IF(AN32="x","x",IF(AN32="-","-","")) | BW32: =IF(AO32="x","x",IF(AO32="-","-","")) | BX32: =IF(AP32="x","x",IF(AP32="-","-","")) | BY32: =IF(AQ32="x","x",IF(AQ32="-","-","")) | BZ32: =IF(AR32="x","x",IF(AR32="-","-","")) | ... CP32: =IF(BH32="x","x",IF(BH32="-","-","")) | CR32: =IF(P32="x","x",IF(P32="-","-","")) -> - | CS32: =IF(Q32="x","x",IF(Q32="-","-","")) -> - | CT32: =IF(R32="x","x",IF(R32="-","-","")) -> - | CU32: =IF(S32="x","x",IF(S32="-","-","")) -> - | CV32: =IF(T32="x","x",IF(T32="-","-","")) -> - | CW32: =IF(U32="x","x",IF(U32="-","-","")) -> - | CX32: =IF(V32="x","x",IF(V32="-","-","")) -> - | CY32: =IF(W32="x","x",IF(W32="-","-","")) -> - | CZ32: - | DA32: - | DB32: - | DC32: - | DE32: =IF(Y32="x","x",IF(Y32="-","-","")) -> - | DF32: =IF(Z32="x","x",IF(Z32="-","-","")) -> - | DG32: =IF(AA32="x","x",IF(AA32="-","-","")) -> - | DH32: =IF(AB32="x","x",IF(AB32="-","-","")) -> - | DI32: =IF(AC32="x","x",IF(AC32="-","-","")) -> - | DJ32: =IF(AD32="x","x",IF(AD32="-","-","")) -> - | DK32: =IF(AE32="x","x",IF(AE32="-","-","")) -> - | DL32: =IF(AF32="x","x",IF(AF32="-","-","")) -> - | DM32: - | DN32: - | DO32: - | DP32: -
A33: yes | B33: 32 | C33: TST032 | D33: yellow | E33: SLink | F33: 32 | G33: - | H33: - | I33: - | J33: no | K33: -20 | L33: no | M33: 640 | N33: - | P33: - | Q33: - | R33: - | S33: - | T33: - | U33: - | V33: - | W33: - | Y33: - | Z33: - | AA33: - | AB33: - | AC33: - | AD33: - | AE33: - | AF33: - | AH33: yes | AI33: yes | AM33: x | BJ33: - | BK33: - | BL33: - | BM33: - | BN33: - | BO33: - | BP33: - | BQ33: - | BS33: =IF(AK33="x","x",IF(AK33="-","-","")) | BT33: =IF(AL33="x","x",IF(AL33="-","-","")) | BU33: =IF(AM33="x","x",IF(AM33="-","-","")) -> x | BV33: =IF(AN33="x","x",IF(AN33="-","-","")) | BW33: =IF(AO33="x","x",IF(AO33="-","-","")) | BX33: =IF(AP33="x","x",IF(AP33="-","-","")) | BY33: =IF(AQ33="x","x",IF(AQ33="-","-","")) | BZ33: =IF(AR33="x","x",IF(AR33="-","-","")) | ... CP33: =IF(BH33="x","x",IF(BH33="-","-","")) | CR33: =IF(P33="x","x",IF(P33="-","-","")) -> - | CS33: =IF(Q33="x","x",IF(Q33="-","-","")) -> - | CT33: =IF(R33="x","x",IF(R33="-","-","")) -> - | CU33: =IF(S33="x","x",IF(S33="-","-","")) -> - | CV33: =IF(T33="x","x",IF(T33="-","-","")) -> - | CW33: =IF(U33="x","x",IF(U33="-","-","")) -> - | CX33: =IF(V33="x","x",IF(V33="-","-","")) -> - | CY33: =IF(W33="x","x",IF(W33="-","-","")) -> - | CZ33: - | DA33: - | DB33: - | DC33: - | DE33: =IF(Y33="x","x",IF(Y33="-","-","")) -> - | DF33: =IF(Z33="x","x",IF(Z33="-","-","")) -> - | DG33: =IF(AA33="x","x",IF(AA33="-","-","")) -> - | DH33: =IF(AB33="x","x",IF(AB33="-","-","")) -> - | DI33: =IF(AC33="x","x",IF(AC33="-","-","")) -> - | DJ33: =IF(AD33="x","x",IF(AD33="-","-","")) -> - | DK33: =IF(AE33="x","x",IF(AE33="-","-","")) -> - | DL33: =IF(AF33="x","x",IF(AF33="-","-","")) -> - | DM33: - | DN33: - | DO33: - | DP33: -
A34: yes | B34: 33 | C34: TST033 | D34: yellow | E34: SLink | F34: 33 | G34: - | H34: - | I34: - | J34: yes | K34: -25 | L34: yes | M34: 660 | N34: - | P34: - | Q34: - | R34: - | S34: - | T34: - | U34: - | V34: - | W34: - | Y34: - | Z34: - | AA34: - | AB34: - | AC34: - | AD34: - | AE34: - | AF34: - | AH34: yes | AI34: yes | AM34: x | BJ34: - | BK34: - | BL34: - | BM34: - | BN34: - | BO34: - | BP34: - | BQ34: - | BS34: =IF(AK34="x","x",IF(AK34="-","-","")) | BT34: =IF(AL34="x","x",IF(AL34="-","-","")) | BU34: =IF(AM34="x","x",IF(AM34="-","-","")) -> x | BV34: =IF(AN34="x","x",IF(AN34="-","-","")) | BW34: =IF(AO34="x","x",IF(AO34="-","-","")) | BX34: =IF(AP34="x","x",IF(AP34="-","-","")) | BY34: =IF(AQ34="x","x",IF(AQ34="-","-","")) | BZ34: =IF(AR34="x","x",IF(AR34="-","-","")) | ... CP34: =IF(BH34="x","x",IF(BH34="-","-","")) | CR34: =IF(P34="x","x",IF(P34="-","-","")) -> - | CS34: =IF(Q34="x","x",IF(Q34="-","-","")) -> - | CT34: =IF(R34="x","x",IF(R34="-","-","")) -> - | CU34: =IF(S34="x","x",IF(S34="-","-","")) -> - | CV34: =IF(T34="x","x",IF(T34="-","-","")) -> - | CW34: =IF(U34="x","x",IF(U34="-","-","")) -> - | CX34: =IF(V34="x","x",IF(V34="-","-","")) -> - | CY34: =IF(W34="x","x",IF(W34="-","-","")) -> - | CZ34: - | DA34: - | DB34: - | DC34: - | DE34: =IF(Y34="x","x",IF(Y34="-","-","")) -> - | DF34: =IF(Z34="x","x",IF(Z34="-","-","")) -> - | DG34: =IF(AA34="x","x",IF(AA34="-","-","")) -> - | DH34: =IF(AB34="x","x",IF(AB34="-","-","")) -> - | DI34: =IF(AC34="x","x",IF(AC34="-","-","")) -> - | DJ34: =IF(AD34="x","x",IF(AD34="-","-","")) -> - | DK34: =IF(AE34="x","x",IF(AE34="-","-","")) -> - | DL34: =IF(AF34="x","x",IF(AF34="-","-","")) -> - | DM34: - | DN34: - | DO34: - | DP34: -
A35: yes | B35: 34 | C35: TST034 | D35: yellow | E35: SLink | F35: 34 | G35: - | H35: - | I35: - | J35: no | K35: -30 | L35: no | M35: 680 | N35: - | P35: - | Q35: - | R35: - | S35: - | T35: - | U35: - | V35: - | W35: - | Y35: - | Z35: - | AA35: - | AB35: - | AC35: - | AD35: - | AE35: - | AF35: - | AH35: yes | AI35: yes | AM35: x | BJ35: - | BK35: - | BL35: - | BM35: - | BN35: - | BO35: - | BP35: - | BQ35: - | BS35: =IF(AK35="x","x",IF(AK35="-","-","")) | BT35: =IF(AL35="x","x",IF(AL35="-","-","")) | BU35: =IF(AM35="x","x",IF(AM35="-","-","")) -> x | BV35: =IF(AN35="x","x",IF(AN35="-","-","")) | BW35: =IF(AO35="x","x",IF(AO35="-","-","")) | BX35: =IF(AP35="x","x",IF(AP35="-","-","")) | BY35: =IF(AQ35="x","x",IF(AQ35="-","-","")) | BZ35: =IF(AR35="x","x",IF(AR35="-","-","")) | ... CP35: =IF(BH35="x","x",IF(BH35="-","-","")) | CR35: =IF(P35="x","x",IF(P35="-","-","")) -> - | CS35: =IF(Q35="x","x",IF(Q35="-","-","")) -> - | CT35: =IF(R35="x","x",IF(R35="-","-","")) -> - | CU35: =IF(S35="x","x",IF(S35="-","-","")) -> - | CV35: =IF(T35="x","x",IF(T35="-","-","")) -> - | CW35: =IF(U35="x","x",IF(U35="-","-","")) -> - | CX35: =IF(V35="x","x",IF(V35="-","-","")) -> - | CY35: =IF(W35="x","x",IF(W35="-","-","")) -> - | CZ35: - | DA35: - | DB35: - | DC35: - | DE35: =IF(Y35="x","x",IF(Y35="-","-","")) -> - | DF35: =IF(Z35="x","x",IF(Z35="-","-","")) -> - | DG35: =IF(AA35="x","x",IF(AA35="-","-","")) -> - | DH35: =IF(AB35="x","x",IF(AB35="-","-","")) -> - | DI35: =IF(AC35="x","x",IF(AC35="-","-","")) -> - | DJ35: =IF(AD35="x","x",IF(AD35="-","-","")) -> - | DK35: =IF(AE35="x","x",IF(AE35="-","-","")) -> - | DL35: =IF(AF35="x","x",IF(AF35="-","-","")) -> - | DM35: - | DN35: - | DO35: - | DP35: -
